<sdf version='1.7'>
  <world name='default'>
    <light name='sun' type='directional'>
      <cast_shadows>1</cast_shadows>
      <pose>0 0 10 0 -0 0</pose>
      <diffuse>0.8 0.8 0.8 1</diffuse>
      <specular>0.2 0.2 0.2 1</specular>
      <attenuation>
        <range>1000</range>
        <constant>0.9</constant>
        <linear>0.01</linear>
        <quadratic>0.001</quadratic>
      </attenuation>
      <direction>-0.5 0.1 -0.9</direction>
      <spot>
        <inner_angle>0</inner_angle>
        <outer_angle>0</outer_angle>
        <falloff>0</falloff>
      </spot>
    </light>
    <model name='ground_plane'>
      <static>1</static>
      <link name='link'>
        <collision name='collision'>
          <geometry>
            <plane>
              <normal>0 0 1</normal>
              <size>100 100</size>
            </plane>
          </geometry>
          <surface>
            <friction>
              <ode>
                <mu>100</mu>
                <mu2>50</mu2>
              </ode>
              <torsional>
                <ode/>
              </torsional>
            </friction>
            <contact>
              <ode/>
            </contact>
            <bounce/>
          </surface>
          <max_contacts>10</max_contacts>
        </collision>
        <visual name='visual'>
          <cast_shadows>0</cast_shadows>
          <geometry>
            <plane>
              <normal>0 0 1</normal>
              <size>100 100</size>
            </plane>
          </geometry>
          <material>
            <script>
              <uri>file://media/materials/scripts/gazebo.material</uri>
              <name>Gazebo/Grey</name>
            </script>
          </material>
        </visual>
        <self_collide>0</self_collide>
        <enable_wind>0</enable_wind>
        <kinematic>0</kinematic>
      </link>
    </model>
    <gravity>0 0 -9.8</gravity>
    <magnetic_field>6e-06 2.3e-05 -4.2e-05</magnetic_field>
    <atmosphere type='adiabatic'/>
    <physics type='ode'>
      <max_step_size>0.001</max_step_size>
      <real_time_factor>1</real_time_factor>
      <real_time_update_rate>1000</real_time_update_rate>
    </physics>
    <scene>
      <ambient>0.4 0.4 0.4 1</ambient>
      <background>0.7 0.7 0.7 1</background>
      <shadows>1</shadows>
    </scene>
    <wind/>
    <spherical_coordinates>
      <surface_model>EARTH_WGS84</surface_model>
      <latitude_deg>0</latitude_deg>
      <longitude_deg>0</longitude_deg>
      <elevation>0</elevation>
      <heading_deg>0</heading_deg>
    </spherical_coordinates>
    <model name='ground_plane_0'>
      <static>1</static>
      <link name='link'>
        <collision name='collision'>
          <geometry>
            <plane>
              <normal>0 0 1</normal>
              <size>100 100</size>
            </plane>
          </geometry>
          <surface>
            <friction>
              <ode>
                <mu>100</mu>
                <mu2>50</mu2>
              </ode>
              <torsional>
                <ode/>
              </torsional>
            </friction>
            <contact>
              <ode/>
            </contact>
            <bounce/>
          </surface>
          <max_contacts>10</max_contacts>
        </collision>
        <visual name='visual'>
          <cast_shadows>0</cast_shadows>
          <geometry>
            <plane>
              <normal>0 0 1</normal>
              <size>100 100</size>
            </plane>
          </geometry>
          <material>
            <script>
              <uri>file://media/materials/scripts/gazebo.material</uri>
              <name>Gazebo/Grey</name>
            </script>
          </material>
        </visual>
        <self_collide>0</self_collide>
        <enable_wind>0</enable_wind>
        <kinematic>0</kinematic>
      </link>
      <pose>4.46962 1.05622 0 0 -0 0</pose>
    </model>
    <state world_name='default'>
      <sim_time>94 277000000</sim_time>
      <real_time>36 125869414</real_time>
      <wall_time>1752743256 83668354</wall_time>
      <iterations>24068</iterations>
      <model name='car'>
        <pose>-9.99999 -10 -0.21 0 -0 0</pose>
        <scale>1 1 1</scale>
        <link name='base_footprint'>
          <pose>-9.99999 -10 -0.21 0 -0 0</pose>
          <velocity>-0 1e-06 2e-06 -1e-06 0 0</velocity>
          <acceleration>-0 -0 -0 0 -0 0</acceleration>
          <wrench>-0 -0 -0 0 -0 0</wrench>
        </link>
        <link name='left_back_wheel'>
          <pose>-10.3 -9.715 0.1 -3e-06 0.000103 0</pose>
          <velocity>-0 1e-06 2e-06 -1.3e-05 -2e-06 0</velocity>
          <acceleration>-0 0 -0 0 -0 0</acceleration>
          <wrench>-0 0 -0 0 -0 0</wrench>
        </link>
        <link name='left_front_wheel'>
          <pose>-9.69999 -9.715 0.1 -4e-06 -0.000291 0</pose>
          <velocity>-0 1e-06 2e-06 -1.3e-05 -2e-06 0</velocity>
          <acceleration>0 -0 -0 0 -0 0</acceleration>
          <wrench>0 -0 -0 0 -0 0</wrench>
        </link>
        <link name='right_back_wheel'>
          <pose>-10.3 -10.285 0.1 -4e-06 0.000104 -0</pose>
          <velocity>-0 1e-06 1e-06 -1.3e-05 -2e-06 0</velocity>
          <acceleration>-0 -0 -0 0 -0 0</acceleration>
          <wrench>-0 -0 -0 0 -0 0</wrench>
        </link>
        <link name='right_front_wheel'>
          <pose>-9.69999 -10.285 0.1 -4e-06 -0.000291 0</pose>
          <velocity>-0 1e-06 1e-06 -1.3e-05 -2e-06 0</velocity>
          <acceleration>0 0 0 0 -0 0</acceleration>
          <wrench>0 0 0 0 -0 0</wrench>
        </link>
      </model>
      <model name='ground_plane'>
        <pose>0 0 0 0 -0 0</pose>
        <scale>1 1 1</scale>
        <link name='link'>
          <pose>0 0 0 0 -0 0</pose>
          <velocity>0 0 0 0 -0 0</velocity>
          <acceleration>0 0 0 0 -0 0</acceleration>
          <wrench>0 0 0 0 -0 0</wrench>
        </link>
      </model>
      <model name='ground_plane_0'>
        <pose>4.46962 1.05622 0 0 -0 0</pose>
        <scale>1 1 1</scale>
        <link name='link'>
          <pose>4.46962 1.05622 0 0 -0 0</pose>
          <velocity>0 0 0 0 -0 0</velocity>
          <acceleration>0 0 0 0 -0 0</acceleration>
          <wrench>0 0 0 0 -0 0</wrench>
        </link>
      </model>
      <model name='shandi'>
        <pose>-1.3287 0.31398 0 0 -0 0</pose>
        <scale>1 1 1</scale>
        <model name='terrain_1'>
          <pose>-1.3287 0.313976 0 0 -0 0</pose>
          <scale>1 1 1</scale>
          <link name='body'>
            <pose>-1.3287 0.313976 0 0 -0 0</pose>
            <velocity>0 0 0 0 -0 0</velocity>
            <acceleration>0 0 0 0 -0 0</acceleration>
            <wrench>0 0 0 0 -0 0</wrench>
          </link>
        </model>
      </model>
      <light name='sun'>
        <pose>0 0 10 0 -0 0</pose>
      </light>
    </state>
    <gui fullscreen='0'>
      <camera name='user_camera'>
        <pose>28.3731 -31.5317 46.851 0 0.925798 2.46505</pose>
        <view_controller>orbit</view_controller>
        <projection_type>perspective</projection_type>
      </camera>
    </gui>
    <model name='car'>
      <link name='base_footprint'>
        <inertial>
          <pose>0.000994 0 0.267535 0 -0 0</pose>
          <mass>0.503</mass>
          <inertia>
            <ixx>0.0391352</ixx>
            <ixy>0</ixy>
            <ixz>-0.000111233</ixz>
            <iyy>0.0393847</iyy>
            <iyz>0</iyz>
            <izz>0.0220848</izz>
          </inertia>
        </inertial>
        <collision name='base_footprint_fixed_joint_lump__car_link_collision'>
          <pose>0 0 0.265 0 -0 0</pose>
          <geometry>
            <box>
              <size>0.5 0.2 0.1</size>
            </box>
          </geometry>
          <surface>
            <contact>
              <ode/>
            </contact>
            <friction>
              <ode/>
              <torsional>
                <ode/>
              </torsional>
            </friction>
            <bounce/>
          </surface>
          <max_contacts>10</max_contacts>
        </collision>
        <collision name='base_footprint_fixed_joint_lump__gps_link_collision_1'>
          <pose>0 0 1.265 0 -0 0</pose>
          <geometry>
            <cylinder>
              <length>0.02</length>
              <radius>0.05</radius>
            </cylinder>
          </geometry>
          <surface>
            <contact>
              <ode/>
            </contact>
            <friction>
              <ode/>
              <torsional>
                <ode/>
              </torsional>
            </friction>
            <bounce/>
          </surface>
          <max_contacts>10</max_contacts>
        </collision>
        <collision name='base_footprint_fixed_joint_lump__imu_link_collision_2'>
          <pose>0 0 0.315 0 -0 0</pose>
          <geometry>
            <box>
              <size>0.03 0.03 0.02</size>
            </box>
          </geometry>
          <surface>
            <contact>
              <ode/>
            </contact>
            <friction>
              <ode/>
              <torsional>
                <ode/>
              </torsional>
            </friction>
            <bounce/>
          </surface>
          <max_contacts>10</max_contacts>
        </collision>
        <collision name='base_footprint_fixed_joint_lump__imu_base_link_collision_3'>
          <pose>0.5 0 0.49 0 -0 0</pose>
          <geometry>
            <box>
              <size>0.03 0.03 0.03</size>
            </box>
          </geometry>
          <surface>
            <contact>
              <ode/>
            </contact>
            <friction>
              <ode/>
              <torsional>
                <ode/>
              </torsional>
            </friction>
            <bounce/>
          </surface>
          <max_contacts>10</max_contacts>
        </collision>
        <collision name='base_footprint_fixed_joint_lump__laser_livox_collision_4'>
          <pose>0.45 0 0.5 0 -0 0</pose>
          <geometry>
            <mesh>
              <scale>1 1 1</scale>
              <uri>/home/mdical/gazebo_map/src/thirdparty/Mid360_simulation_plugin-main/livox_laser_simulation/meshes/livox_mid-360-90x.dae</uri>
            </mesh>
          </geometry>
          <surface>
            <contact>
              <ode/>
            </contact>
            <friction>
              <ode/>
              <torsional>
                <ode/>
              </torsional>
            </friction>
            <bounce/>
          </surface>
          <max_contacts>10</max_contacts>
        </collision>
        <visual name='base_footprint_visual'>
          <pose>0 0 0 0 -0 0</pose>
          <geometry>
            <sphere>
              <radius>0.001</radius>
            </sphere>
          </geometry>
        </visual>
        <visual name='base_footprint_fixed_joint_lump__car_link_visual_1'>
          <pose>0 0 0.665 0 -0 0</pose>
          <geometry>
            <box>
              <size>0.8 0.5 0.5</size>
            </box>
          </geometry>
          <material>
            <script>
              <name>Gazebo/Blue</name>
              <uri>file://media/materials/scripts/gazebo.material</uri>
            </script>
          </material>
        </visual>
        <visual name='base_footprint_fixed_joint_lump__gps_link_visual_2'>
          <pose>0 0 1.265 0 -0 0</pose>
          <geometry>
            <cylinder>
              <length>0.02</length>
              <radius>0.05</radius>
            </cylinder>
          </geometry>
          <material>
            <script>
              <name>Gazebo/Red</name>
              <uri>file://media/materials/scripts/gazebo.material</uri>
            </script>
          </material>
        </visual>
        <visual name='base_footprint_fixed_joint_lump__imu_link_visual_3'>
          <pose>0 0 0.315 0 -0 0</pose>
          <geometry>
            <box>
              <size>0.03 0.03 0.02</size>
            </box>
          </geometry>
          <material>
            <script>
              <name>Gazebo/Blue</name>
              <uri>file://media/materials/scripts/gazebo.material</uri>
            </script>
          </material>
        </visual>
        <visual name='base_footprint_fixed_joint_lump__imu_base_link_visual_4'>
          <pose>0.5 0 0.49 0 -0 0</pose>
          <geometry>
            <box>
              <size>0.03 0.03 0.03</size>
            </box>
          </geometry>
          <material>
            <script>
              <name>Gazebo/Green</name>
              <uri>file://media/materials/scripts/gazebo.material</uri>
            </script>
          </material>
        </visual>
        <visual name='base_footprint_fixed_joint_lump__laser_livox_visual_5'>
          <pose>0.45 0 0.5 0 -0 0</pose>
          <geometry>
            <mesh>
              <scale>1 1 1</scale>
              <uri>/home/mdical/gazebo_map/src/thirdparty/Mid360_simulation_plugin-main/livox_laser_simulation/meshes/livox_mid-360-90x.dae</uri>
            </mesh>
          </geometry>
        </visual>
        <gravity>0</gravity>
        <gravity>1</gravity>
        <sensor name='imu_sensor' type='imu'>
          <always_on>1</always_on>
          <update_rate>10</update_rate>
          <visualize>1</visualize>
          <topic>/livox/imu</topic>
          <plugin name='imu_plugin' filename='libgazebo_ros_imu_sensor.so'>
            <topicName>/livox/imu</topicName>
            <bodyName>imu_base_link</bodyName>
            <updateRateHZ>10.0</updateRateHZ>
            <gaussianNoise>0.00329</gaussianNoise>
            <xyzOffset>0 0 0</xyzOffset>
            <rpyOffset>0 0 0</rpyOffset>
            <frameName>imu_link</frameName>
            <robotNamespace>/</robotNamespace>
          </plugin>
          <pose>0.5 0 0.49 0 -0 0</pose>
          <imu/>
        </sensor>
        <sensor name='laser_livox' type='ray'>
          <visualize>1</visualize>
          <always_on>1</always_on>
          <update_rate>10</update_rate>
          <plugin name='gazebo_ros_laser_controller' filename='liblivox_laser_simulation.so'>
            <ray>
              <scan>
                <horizontal>
                  <samples>100</samples>
                  <resolution>1</resolution>
                  <min_angle>-3.1415926535897931</min_angle>
                  <max_angle>3.1415926535897931</max_angle>
                </horizontal>
                <vertical>
                  <samples>50</samples>
                  <resolution>1</resolution>
                  <min_angle>-3.1415926535897931</min_angle>
                  <max_angle>3.1415926535897931</max_angle>
                </vertical>
              </scan>
              <range>
                <min>0.1</min>
                <max>40</max>
                <resolution>1</resolution>
              </range>
              <noise>
                <type>gaussian</type>
                <mean>0.0</mean>
                <stddev>0.0</stddev>
              </noise>
            </ray>
            <visualize>0</visualize>
            <samples>20000</samples>
            <downsample>1</downsample>
            <csv_file_name>mid360-real-centr.csv</csv_file_name>
            <publish_pointcloud_type>2</publish_pointcloud_type>
            <ros_topic>/livox/lidar</ros_topic>
            <frameName>laser_livox</frameName>
            <robotNamespace>/</robotNamespace>
          </plugin>
          <pose>0.45 0 0.55 0 -0 0</pose>
          <ray>
            <scan>
              <horizontal>
                <samples>640</samples>
                <resolution>1</resolution>
                <min_angle>0</min_angle>
                <max_angle>0</max_angle>
              </horizontal>
              <vertical>
                <samples>1</samples>
                <min_angle>0</min_angle>
                <max_angle>0</max_angle>
              </vertical>
            </scan>
            <range>
              <min>0</min>
              <max>0</max>
            </range>
          </ray>
        </sensor>
        <self_collide>0</self_collide>
        <enable_wind>0</enable_wind>
        <kinematic>0</kinematic>
      </link>
      <joint name='left_back_wheel2base_link' type='revolute'>
        <pose relative_to='base_footprint'>-0.3 0.285 0.31 0 -0 0</pose>
        <parent>base_footprint</parent>
        <child>left_back_wheel</child>
        <axis>
          <xyz>0 1 0</xyz>
          <limit>
            <lower>-1e+16</lower>
            <upper>1e+16</upper>
          </limit>
          <dynamics>
            <spring_reference>0</spring_reference>
            <spring_stiffness>0</spring_stiffness>
          </dynamics>
        </axis>
      </joint>
      <link name='left_back_wheel'>
        <pose relative_to='left_back_wheel2base_link'>0 0 0 0 -0 0</pose>
        <inertial>
          <pose>0 0 0 0 -0 0</pose>
          <mass>0.5</mass>
          <inertia>
            <ixx>0.00145417</ixx>
            <ixy>0</ixy>
            <ixz>0</ixz>
            <iyy>0.00145417</iyy>
            <iyz>0</iyz>
            <izz>0.0025</izz>
          </inertia>
        </inertial>
        <collision name='left_back_wheel_collision'>
          <pose>0 0 0 1.5708 -0 0</pose>
          <geometry>
            <cylinder>
              <length>0.07</length>
              <radius>0.1</radius>
            </cylinder>
          </geometry>
          <surface>
            <contact>
              <ode>
                <kp>1e+07</kp>
                <kd>1</kd>
              </ode>
            </contact>
            <friction>
              <ode>
                <mu>100000</mu>
                <mu2>100000</mu2>
              </ode>
              <torsional>
                <ode/>
              </torsional>
            </friction>
            <bounce/>
          </surface>
          <max_contacts>10</max_contacts>
        </collision>
        <visual name='left_back_wheel_visual'>
          <pose>0 0 0 1.5708 -0 0</pose>
          <geometry>
            <cylinder>
              <length>0.07</length>
              <radius>0.1</radius>
            </cylinder>
          </geometry>
          <material>
            <script>
              <name>Gazebo/Black</name>
              <uri>file://media/materials/scripts/gazebo.material</uri>
            </script>
          </material>
        </visual>
        <self_collide>0</self_collide>
        <enable_wind>0</enable_wind>
        <kinematic>0</kinematic>
      </link>
      <joint name='left_front_wheel2base_link' type='revolute'>
        <pose relative_to='base_footprint'>0.3 0.285 0.31 0 -0 0</pose>
        <parent>base_footprint</parent>
        <child>left_front_wheel</child>
        <axis>
          <xyz>0 1 0</xyz>
          <limit>
            <lower>-1e+16</lower>
            <upper>1e+16</upper>
          </limit>
          <dynamics>
            <spring_reference>0</spring_reference>
            <spring_stiffness>0</spring_stiffness>
          </dynamics>
        </axis>
      </joint>
      <link name='left_front_wheel'>
        <pose relative_to='left_front_wheel2base_link'>0 0 0 0 -0 0</pose>
        <inertial>
          <pose>0 0 0 0 -0 0</pose>
          <mass>0.5</mass>
          <inertia>
            <ixx>0.00145417</ixx>
            <ixy>0</ixy>
            <ixz>0</ixz>
            <iyy>0.00145417</iyy>
            <iyz>0</iyz>
            <izz>0.0025</izz>
          </inertia>
        </inertial>
        <collision name='left_front_wheel_collision'>
          <pose>0 0 0 1.5708 -0 0</pose>
          <geometry>
            <cylinder>
              <length>0.07</length>
              <radius>0.1</radius>
            </cylinder>
          </geometry>
          <surface>
            <contact>
              <ode>
                <kp>1e+07</kp>
                <kd>1</kd>
              </ode>
            </contact>
            <friction>
              <ode>
                <mu>100000</mu>
                <mu2>100000</mu2>
              </ode>
              <torsional>
                <ode/>
              </torsional>
            </friction>
            <bounce/>
          </surface>
          <max_contacts>10</max_contacts>
        </collision>
        <visual name='left_front_wheel_visual'>
          <pose>0 0 0 1.5708 -0 0</pose>
          <geometry>
            <cylinder>
              <length>0.07</length>
              <radius>0.1</radius>
            </cylinder>
          </geometry>
          <material>
            <script>
              <name>Gazebo/Black</name>
              <uri>file://media/materials/scripts/gazebo.material</uri>
            </script>
          </material>
        </visual>
        <self_collide>0</self_collide>
        <enable_wind>0</enable_wind>
        <kinematic>0</kinematic>
      </link>
      <joint name='right_back_wheel2base_link' type='revolute'>
        <pose relative_to='base_footprint'>-0.3 -0.285 0.31 0 -0 0</pose>
        <parent>base_footprint</parent>
        <child>right_back_wheel</child>
        <axis>
          <xyz>0 1 0</xyz>
          <limit>
            <lower>-1e+16</lower>
            <upper>1e+16</upper>
          </limit>
          <dynamics>
            <spring_reference>0</spring_reference>
            <spring_stiffness>0</spring_stiffness>
          </dynamics>
        </axis>
      </joint>
      <link name='right_back_wheel'>
        <pose relative_to='right_back_wheel2base_link'>0 0 0 0 -0 0</pose>
        <inertial>
          <pose>0 0 0 0 -0 0</pose>
          <mass>0.5</mass>
          <inertia>
            <ixx>0.00145417</ixx>
            <ixy>0</ixy>
            <ixz>0</ixz>
            <iyy>0.00145417</iyy>
            <iyz>0</iyz>
            <izz>0.0025</izz>
          </inertia>
        </inertial>
        <collision name='right_back_wheel_collision'>
          <pose>0 0 0 1.5708 -0 0</pose>
          <geometry>
            <cylinder>
              <length>0.07</length>
              <radius>0.1</radius>
            </cylinder>
          </geometry>
          <surface>
            <contact>
              <ode>
                <kp>1e+07</kp>
                <kd>1</kd>
              </ode>
            </contact>
            <friction>
              <ode>
                <mu>100000</mu>
                <mu2>100000</mu2>
              </ode>
              <torsional>
                <ode/>
              </torsional>
            </friction>
            <bounce/>
          </surface>
          <max_contacts>10</max_contacts>
        </collision>
        <visual name='right_back_wheel_visual'>
          <pose>0 0 0 1.5708 -0 0</pose>
          <geometry>
            <cylinder>
              <length>0.07</length>
              <radius>0.1</radius>
            </cylinder>
          </geometry>
          <material>
            <script>
              <name>Gazebo/Black</name>
              <uri>file://media/materials/scripts/gazebo.material</uri>
            </script>
          </material>
        </visual>
        <self_collide>0</self_collide>
        <enable_wind>0</enable_wind>
        <kinematic>0</kinematic>
      </link>
      <joint name='right_front_wheel2base_link' type='revolute'>
        <pose relative_to='base_footprint'>0.3 -0.285 0.31 0 -0 0</pose>
        <parent>base_footprint</parent>
        <child>right_front_wheel</child>
        <axis>
          <xyz>0 1 0</xyz>
          <limit>
            <lower>-1e+16</lower>
            <upper>1e+16</upper>
          </limit>
          <dynamics>
            <spring_reference>0</spring_reference>
            <spring_stiffness>0</spring_stiffness>
          </dynamics>
        </axis>
      </joint>
      <link name='right_front_wheel'>
        <pose relative_to='right_front_wheel2base_link'>0 0 0 0 -0 0</pose>
        <inertial>
          <pose>0 0 0 0 -0 0</pose>
          <mass>0.5</mass>
          <inertia>
            <ixx>0.00145417</ixx>
            <ixy>0</ixy>
            <ixz>0</ixz>
            <iyy>0.00145417</iyy>
            <iyz>0</iyz>
            <izz>0.0025</izz>
          </inertia>
        </inertial>
        <collision name='right_front_wheel_collision'>
          <pose>0 0 0 1.5708 -0 0</pose>
          <geometry>
            <cylinder>
              <length>0.07</length>
              <radius>0.1</radius>
            </cylinder>
          </geometry>
          <surface>
            <contact>
              <ode>
                <kp>1e+07</kp>
                <kd>1</kd>
              </ode>
            </contact>
            <friction>
              <ode>
                <mu>100000</mu>
                <mu2>100000</mu2>
              </ode>
              <torsional>
                <ode/>
              </torsional>
            </friction>
            <bounce/>
          </surface>
          <max_contacts>10</max_contacts>
        </collision>
        <visual name='right_front_wheel_visual'>
          <pose>0 0 0 1.5708 -0 0</pose>
          <geometry>
            <cylinder>
              <length>0.07</length>
              <radius>0.1</radius>
            </cylinder>
          </geometry>
          <material>
            <script>
              <name>Gazebo/Black</name>
              <uri>file://media/materials/scripts/gazebo.material</uri>
            </script>
          </material>
        </visual>
        <self_collide>0</self_collide>
        <enable_wind>0</enable_wind>
        <kinematic>0</kinematic>
      </link>
      <plugin name='skid_steer_drive_controller' filename='libgazebo_ros_skid_steer_drive.so'>
        <updateRate>100.0</updateRate>
        <robotNamespace>/</robotNamespace>
        <publishTf>1</publishTf>
        <leftFrontJoint>left_front_wheel2base_link</leftFrontJoint>
        <rightFrontJoint>right_front_wheel2base_link</rightFrontJoint>
        <leftRearJoint>left_back_wheel2base_link</leftRearJoint>
        <rightRearJoint>right_back_wheel2base_link</rightRearJoint>
        <wheelSeparation>1</wheelSeparation>
        <wheelDiameter>0.2</wheelDiameter>
        <torque>1000</torque>
        <maxVelocity>5.0</maxVelocity>
        <maxAcceleration>3.0</maxAcceleration>
        <commandTopic>cmd_vel</commandTopic>
        <topicName>cmd_vel</topicName>
        <odometryTopic>odom</odometryTopic>
        <odometryFrame>odom</odometryFrame>
        <robotBaseFrame>base_footprint</robotBaseFrame>
        <publishOdomTF>1</publishOdomTF>
        <broadcastTF>1</broadcastTF>
        <wheelTorque>1000</wheelTorque>
        <wheelAcceleration>3.0</wheelAcceleration>
        <wheelDeceleration>3.0</wheelDeceleration>
        <turningMultiplier>2.0</turningMultiplier>
        <wheelSeparationMultiplier>1.0</wheelSeparationMultiplier>
      </plugin>
      <plugin name='gps_plugin' filename='libhector_gazebo_ros_gps.so'>
        <robotNamespace>/</robotNamespace>
        <topicName>/gps/fix</topicName>
        <frameId>gps_link</frameId>
        <referenceLatitude>47.0</referenceLatitude>
        <referenceLongitude>8.0</referenceLongitude>
        <referenceAltitude>0.0</referenceAltitude>
        <referenceHeading>89.00</referenceHeading>
        <gaussianNoise>0.00 0.00 0.00</gaussianNoise>
        <drift>0 0 0</drift>
        <velocityGaussianNoise>0 0 0</velocityGaussianNoise>
        <offset>0 0 0</offset>
        <bodyName>base_footprint</bodyName>
        <xyzOffset>0 0 1.265</xyzOffset>
        <rpyOffset>0 -0 0</rpyOffset>
        <ignition::corrected_offsets>1</ignition::corrected_offsets>
      </plugin>
      <plugin name='imu_plugin' filename='libhector_gazebo_ros_imu.so'>
        <robotNamespace>/</robotNamespace>
        <topicName>/imu/data</topicName>
        <frameId>imu_link</frameId>
        <bodyName>base_footprint</bodyName>
        <xyzOffset>0 0 0.315</xyzOffset>
        <rpyOffset>0 -0 0</rpyOffset>
        <ignition::corrected_offsets>1</ignition::corrected_offsets>
      </plugin>
      <frame name='gps_joint' attached_to='car_link'>
        <pose>0 0 1 0 -0 0</pose>
      </frame>
      <frame name='gps_link' attached_to='gps_joint'/>
      <frame name='imu_joint' attached_to='car_link'>
        <pose>0 0 0.05 0 -0 0</pose>
      </frame>
      <frame name='imu_link' attached_to='imu_joint'/>
      <frame name='base_link2base_footprint' attached_to='base_footprint'>
        <pose>0 0 0.265 0 -0 0</pose>
      </frame>
      <frame name='car_link' attached_to='base_link2base_footprint'/>
      <frame name='imu_platform_joint' attached_to='base_test_link'>
        <pose>0.05 0 -0.01 0 -0 0</pose>
      </frame>
      <frame name='imu_base_link' attached_to='imu_platform_joint'/>
      <frame name='laser_livox_joint' attached_to='base_test_link'>
        <pose>0 0 0 0 -0 0</pose>
      </frame>
      <frame name='laser_livox' attached_to='laser_livox_joint'/>
      <frame name='base_link_joint' attached_to='base_footprint'>
        <pose>0.45 0 0.5 0 -0 0</pose>
      </frame>
      <frame name='base_test_link' attached_to='base_link_joint'/>
      <pose>-10 -10 0 0 -0 0</pose>
    </model>
    <model name='shandi'>
      <model name='terrain_1'>
        <pose>-4e-06 -4e-06 0 0 -0 0</pose>
        <static>1</static>
        <link name='body'>
          <visual name='visual'>
            <geometry>
              <mesh>
                <uri>model://terrain_1/media/terrain_1.dae</uri>
              </mesh>
            </geometry>
            <material>
              <script>
                <uri>model://terrain_1/media/scripts</uri>
                <uri>model://terrain_1/media/Textures</uri>
                <name>RepeatedGrass/Diffuse</name>
              </script>
            </material>
          </visual>
          <collision name='collision'>
            <geometry>
              <mesh>
                <uri>model://terrain_1/media/terrain_1.dae</uri>
              </mesh>
            </geometry>
            <max_contacts>10</max_contacts>
            <surface>
              <contact>
                <ode/>
              </contact>
              <bounce/>
              <friction>
                <torsional>
                  <ode/>
                </torsional>
                <ode/>
              </friction>
            </surface>
          </collision>
          <self_collide>0</self_collide>
          <enable_wind>0</enable_wind>
          <kinematic>0</kinematic>
        </link>
      </model>
      <static>0</static>
      <allow_auto_disable>1</allow_auto_disable>
      <pose>-2.68623 3.1308 0 0 -0 0</pose>
    </model>
  </world>
</sdf>
